Workbook

Sheet Introduction
A2: Project Name
A6: What is this? | B6: This workbook is meant to help manage and piroritize the user stories and features using scrum.
A11: How to use and read this document? | B11: Before project start: The product owner is responsible for managing and maintaining the product backlog of user stories.
B12: Before each sprint: The vendor will break down the user stories into tasks.
A15: Notes | B15: Cells that you can edit have a blue background.
B16: Sprints are assumed to be 2 weeks long (10 working days)/
A18: Licence | B18: This work is licensed under a Creative Commons Attribution-Share Alike 3.0 Unported License.
A23: Origins | B23: This work is inspired by the Scrum Template published by Nicolas Martignole on his "Touilleur Express" blog. Adapted by Olivier Gérardin.

Sheet Product backlog
A2: AceReads - Bookstore Management System
B4: Organizations | C4: Ana's Anomalous Anthologies
B5: Project | C5: AceReads
B6: Product Owner | C6: Juana Rodriguez
B7: Scrum Master | C7: Tracy Pillow
B8: Development Team | C8: Ali Osman, Kyonna Robinson, Juana Rodriguez, Nathan Horstmeier, Phillip Williams
A10: Story ID | B10: Title | C10: Description | D10: s | E10: Priority # | F10: Sprint # | G10: Responsibility
A11: EPIC-001 | B11: User Registration & Authentication | C11: As a user, I want to register and securely log into the system so that I can access personalized features and my account information is protected. | D11: 1. Users can register with email, password (min 8 chars, 1 uppercase, 1 number, 1 special char) 2. Email verification is required before account activation 3. Password is encrypted using industry-standard hashing (bcrypt) 4. Users can log in with valid credentials 5. Failed login attempts are limited (max 5) with account lockout 6. Password reset functionality via secure email link 7. Session timeout after 30 minutes of inactivity | E11: 1 | F11: 1 | G11: Ali Osman (T1-001, T1-002), Juana Rodriguez (T1-003), Kyonna Robinson (T1-004)
A12: EPIC-002 | B12: Book Inventory Management | C12: As a store manager, I want to manage the book inventory so that I can add, update, and track all books in the system with accurate stock levels. | D12: 1. Admin can add new books with ISBN, title, author, price, quantity, category, publisher, publication date 2. Admin can update existing book information 3. Admin can delete books (soft delete to maintain history) 4. System displays real-time stock levels 5. Low stock alerts triggered when quantity falls below threshold 6. Bulk import of books via CSV/Excel file 7. Book images can be uploaded and displayed 8. Search and filter books by multiple criteria | E12: 1 | F12: 1 | G12: Nathan Horstmeier (T1-005, T1-006, T1-007)
A13: EPIC-003 | B13: Book Search & Catalog Browsing | C13: As a customer, I want to search and browse books so that I can easily find books I'm interested in purchasing. | D13: 1. Search by title, author, ISBN, or keyword 2. Filter results by category, price range, availability, rating 3. Sort results by relevance, price, date, popularity 4. Display book details including description, reviews, ratings 5. Search results load within 2 seconds 6. Auto-suggest/autocomplete functionality 7. Browse by categories and subcategories 8. Recently viewed books history | E13: 2 | F13: 1 | G13: Nathan Horstmeier (T1-008 through T1-011), Kyonna Robinson (T1-011)
A14: EPIC-004 | B14: Shopping Cart & Checkout Process | C14: As a customer, I want to add books to a shopping cart and complete purchases so that I can buy multiple books in a single transaction. | D14: 1. Add/remove books from cart 2. Update quantities in cart 3. Cart persists across sessions for logged-in users 4. Display itemized cart with subtotal, taxes, shipping 5. Apply discount codes/coupons 6. Multiple shipping address options 7. Order summary before final confirmation 8. Email confirmation sent upon successful order 9. Cart abandonment recovery emails | E14: 1 | F14: 2 | G14: Phillip Williams
A15: EPIC-005 | B15: Secure Payment Processing | C15: As a customer, I want to make secure payments so that my financial information is protected and I can complete transactions safely. | D15: 1. Integration with PCI-DSS compliant payment gateway 2. Support multiple payment methods (credit/debit cards, PayPal, digital wallets) 3. Card details are never stored on local servers 4. SSL/TLS encryption for all payment transactions 5. Payment confirmation and receipt generation 6. Refund processing capability 7. Transaction logging for audit purposes 8. Fraud detection mechanisms in place | E15: 1 | F15: 2 | G15: Development Team
A16: EPIC-006 | B16: Order Management System | C16: As a store manager, I want to manage customer orders so that I can track order status, process shipments, and handle returns efficiently. | D16: 1. View all orders with filtering by status, date, customer 2. Update order status (pending, processing, shipped, delivered, cancelled) 3. Generate shipping labels and tracking numbers 4. Send automated status update notifications to customers 5. Process returns and refunds 6. Order history maintained for minimum 7 years 7. Generate order reports and analytics 8. Handle partial shipments | E16: 2 | F16: 2 | G16: Development Team
A17: EPIC-007 | B17: Customer Account Management | C17: As a customer, I want to manage my account profile so that I can update my information, view order history, and manage preferences. | D17: 1. View and edit personal information 2. Manage multiple shipping/billing addresses 3. View complete order history 4. Track current orders in real-time 5. Manage wishlist/favorites 6. Set communication preferences 7. View and manage saved payment methods (tokenized) 8. Download invoices/receipts 9. Account deletion option (GDPR compliance) | E17: 2 | F17: 3 | G17: Development Team
A18: EPIC-008 | B18: Book Reviews & Ratings System | C18: As a customer, I want to read and write book reviews so that I can make informed purchasing decisions and share my opinions with other readers. | D18: 1. Submit star ratings (1-5) for purchased books 2. Write text reviews with character limit 3. Edit or delete own reviews 4. View average ratings and total review count 5. Sort reviews by date, rating, helpfulness 6. Mark reviews as helpful 7. Admin moderation of inappropriate content 8. Verified purchase badge on reviews | E18: 3 | F18: 3 | G18: Development Team
A19: EPIC-009 | B19: Reporting & Business Analytics | C19: As a store manager, I want to access reports and analytics so that I can make data-driven business decisions and monitor store performance. | D19: 1. Sales reports by period, category, author 2. Inventory reports with stock levels and turnover 3. Customer analytics (demographics, behavior) 4. Revenue and profit margin reports 5. Best-selling books reports 6. Export reports to PDF, Excel, CSV 7. Dashboard with key performance indicators 8. Customizable date ranges for all reports 9. Scheduled automated report generation | E19: 2 | F19: 4 | G19: Development Team
A20: EPIC-010 | B20: Security & Data Protection | C20: As a system administrator, I want to ensure comprehensive security measures so that customer data is protected and the system is secure from threats. | D20: 1. Role-based access control (RBAC) implemented 2. All sensitive data encrypted at rest and in transit 3. Regular automated security vulnerability scanning 4. Audit logs for all administrative actions 5. IP-based access restrictions for admin panel 6. Two-factor authentication (2FA) for admin accounts 7. Regular automated backups with encryption 8. GDPR and data privacy compliance 9. SQL injection and XSS prevention measures 10. Rate limiting to prevent DDoS attacks | E20: 1 | F20: 1 | G20: Nathan Horstmeier (T1-012, T1-013)
A21: EPIC-011 | B21: Notifications & Communication System | C21: As a customer, I want to receive relevant notifications so that I stay informed about my orders, promotions, and new arrivals. | D21: 1. Email notifications for order confirmations, shipping, delivery 2. Promotional email campaigns with opt-in/opt-out 3. New arrival notifications for favorite categories/authors 4. Back-in-stock notifications 5. Price drop alerts for wishlist items 6. SMS notifications option for order updates 7. In-app notification center 8. Unsubscribe option in all communications | E21: 3 | F21: 4 | G21: Development Team
A22: EPIC-012 | B22: Administrative Dashboard | C22: As an administrator, I want a centralized dashboard so that I can efficiently manage all aspects of the bookstore operations. | D22: 1. Overview of daily/weekly/monthly sales 2. Pending orders requiring attention 3. Low stock alerts prominently displayed 4. Recent customer activity feed 5. Quick access to all management modules 6. System health and performance metrics 7. User management capabilities 8. Content management for banners/promotions 9. Responsive design for mobile access | E22: 2 | F22: 3 | G22: Development Team
... A25: EPIC-015 | B25: Mobile-Responsive Design | C25: As a customer, I want to access the bookstore from any device so that I can browse and purchase books conveniently from my smartphone or tablet. | D25: 1. Fully responsive design across all screen sizes 2. Touch-friendly navigation and buttons 3. Optimized images for mobile bandwidth 4. Mobile-specific features (tap to call, maps integration) 5. Fast loading times on mobile networks (<3 seconds) 6. Consistent experience across iOS and Android browsers 7. Mobile checkout optimization 8. Progressive Web App (PWA) capabilities | E25: 2 | F25: 4 | G25: Development Team

Sheet Sprint 1
A2: =CONCATENATE("Sprint #",E5, "Tracking Sheet")
C4: Project | E4: AceReads
C5: Sprint # | E5: 1
C6: Start date | E6: 46181
D7: Total Team Members | E7: 5
F8: week 1 | M8: week 2
F9: 1 | G9: 2 | H9: 3 | I9: 4 | J9: 5 | K9: 6 | L9: 7 | M9: 8 | N9: 9 | O9: 10 | P9: 11 | Q9: 12 | R9: 13 | S9: 14
A10: Task ID | B10: Story ID | C10: Description | D10: Responsibility | E10: Initial estimate | F10: =E6 | G10: =F10+1 | H10: =G10+1 | I10: =H10+1 | J10: =I10+1 | K10: =J10+1 | L10: =K10+1 | M10: =L10+1 | N10: =M10+1 | ... S10: =R10+1 | T10: Actual Completed By
A11: T1-001 | B11: EPIC-001 | C11: Design & implement user registration (DB, API, UI) | D11: Ali Osman | E11: 12 | F11: 12 | G11: 10 | H11: 8 | I11: 5 | J11: 0 | K11: 0 | L11: 0 | M11: 0 | N11: 0 | O11: 0 | P11: 0 | Q11: 0 | R11: 0 | S11: 0 | T11: Ali Osman
A12: T1-002 | B12: EPIC-001 | C12: Implement password encryption & validation | D12: Ali Osman | E12: 6 | F12: 6 | G12: 5 | H12: 3 | I12: 0 | J12: 0 | K12: 0 | L12: 0 | M12: 0 | N12: 0 | O12: 0 | P12: 0 | Q12: 0 | R12: 0 | S12: 0 | T12: Ali Osman
A13: T1-003 | B13: EPIC-001 | C13: Create login system with session management | D13: Juana Rodriguez | E13: 10 | F13: 10 | G13: 10 | H13: 10 | I13: 8 | J13: 5 | K13: 2 | L13: 0 | M13: 0 | N13: 0 | O13: 0 | P13: 0 | Q13: 0 | R13: 0 | S13: 0 | T13: Juana Rodriguez
A14: T1-004 | B14: EPIC-001 | C14: Build login/registration UI with error handling | D14: Kyonna Robinson | E14: 8 | F14: 8 | G14: 8 | H14: 8 | I14: 6 | J14: 4 | K14: 2 | L14: 0 | M14: 0 | N14: 0 | O14: 0 | P14: 0 | Q14: 0 | R14: 0 | S14: 0 | T14: Kyonna Robinson
A15: T1-005 | B15: EPIC-002 | C15: Design book inventory database schema | D15: Nathan Horstmeier | E15: 6 | F15: 6 | G15: 6 | H15: 6 | I15: 6 | J15: 6 | K15: 6 | L15: 6 | M15: 4 | N15: 2 | O15: 0 | P15: 0 | Q15: 0 | R15: 0 | S15: 0 | T15: Nathan Horstmeier
A16: T1-006 | B16: EPIC-002 | C16: Create CRUD APIs for book management | D16: Nathan Horstmeier | E16: 12 | F16: 12 | G16: 12 | H16: 12 | I16: 12 | J16: 12 | K16: 10 | L16: 8 | M16: 6 | N16: 4 | O16: 2 | P16: 0 | Q16: 0 | R16: 0 | S16: 0 | T16: Nathan Horstmeier
A17: T1-007 | B17: EPIC-002 | C17: Build admin book management interface | D17: Nathan Horstmeier | E17: 10 | F17: 10 | G17: 10 | H17: 10 | I17: 10 | J17: 10 | K17: 10 | L17: 10 | M17: 8 | N17: 6 | O17: 4 | P17: 2 | Q17: 0 | R17: 0 | S17: 0 | T17: Nathan Horstmeier
A18: T1-008 | B18: EPIC-003 | C18: Implement book search & filtering backend | D18: Juana Rodriguez | E18: 6 | F18: 6 | G18: 6 | H18: 6 | I18: 6 | J18: 6 | K18: 6 | L18: 6 | M18: 6 | N18: 6 | O18: 0 | P18: 0 | Q18: 0 | R18: 0 | S18: 0 | T18: Juana Rodriguez
A19: T1-009 | B19: EPIC-003 | C19: Configure security (SSL, RBAC, input validation) | D19: Nathan Horstmeier | E19: 8 | F19: 8 | G19: 8 | H19: 8 | I19: 8 | J19: 8 | K19: 8 | L19: 8 | M19: 8 | N19: 6 | O19: 4 | P19: 2 | Q19: 0 | R19: 0 | S19: 0 | T19: Nathan Horstmeier
A20: T1-010 | B20: EPIC-003 | C20: Implement book search functionality | D20: Juana Rodriguez | E20: 10 | F20: 10 | G20: 10 | H20: 10 | I20: 10 | J20: 10 | K20: 10 | L20: 10 | M20: 8 | N20: 0 | O20: 0 | P20: 0 | Q20: 0 | R20: 0 | S20: 0 | T20: Juana Rodriguez
A21: T1-011 | B21: EPIC-003 | C21: Build search results UI with filters | D21: Kyonna Robinson | E21: 6 | F21: 6 | G21: 6 | H21: 6 | I21: 6 | J21: 6 | K21: 6 | L21: 6 | M21: 6 | N21: 4 | O21: 2 | P21: 0 | Q21: 0 | R21: 0 | S21: 0 | T21: Kyonna Robinson
A22: T1-012 | B22: EPIC-010 | C22: Implement SSL/TLS security configuration | D22: Nathan Horstmeier | E22: 4 | F22: 4 | G22: 4 | H22: 4 | I22: 4 | J22: 4 | K22: 4 | L22: 4 | M22: 4 | N22: 2 | O22: 0 | P22: 0 | Q22: 0 | R22: 0 | S22: 0 | T22: Nathan Horstmeier
A23: T1-013 | B23: EPIC-010 | C23: Set up role-based access control (RBAC) | D23: Nathan Horstmeier | E23: 6 | F23: 6 | G23: 6 | H23: 6 | I23: 6 | J23: 6 | K23: 6 | L23: 6 | M23: 4 | N23: 2 | O23: 0 | P23: 0 | Q23: 0 | R23: 0 | S23: 0 | T23: Nathan Horstmeier
C25: Remaining units (actual) | E25: 104 | F25: =SUM(F11:F24) | G25: =SUM(G11:G24) | H25: =SUM(H11:H24) | I25: =SUM(I11:I24) | J25: =SUM(J11:J24) | K25: =SUM(K11:K24) | L25: =SUM(L11:L24) | M25: =SUM(M11:M24) | ... S25: =SUM(S11:S24)
C26: Remaining units (ideal) | F26: =SUM($E$11:$E$24) | G26: =F26-($E$25/14) | H26: =G26-($E$25/14) | I26: =H26-($E$25/14) | J26: =I26-($E$25/14) | K26: =J26-($E$25/14) | L26: =K26-($E$25/14) | M26: =L26-($E$25/14) | N26: =M26-($E$25/14) | ... S26: =R26-($E$25/14)
A28: Actual completion note: Original task assignments were revised mid-sprint as the team coordinated workloads. Final responsibilities reflect who completed each task. All 13 tasks were delivered by Sprint 1 end date.

Sheet Sprint 2
A2: =CONCATENATE("Sprint #",E5, "Tracking Sheet")
C4: Project | E4: AceReads
C5: Sprint # | E5: 2
C6: Start date | E6: 46188
D7: Total Team Members | E7: 5
F8: week 1 | M8: week 2
F9: 1 | G9: 2 | H9: 3 | I9: 4 | J9: 5 | K9: 6 | L9: 7 | M9: 8 | N9: 9 | O9: 10 | P9: 11 | Q9: 12 | R9: 13 | S9: 14
A10: Task ID | B10: Story ID | C10: Description | D10: Phillip Williams | E10: Initial estimate | F10: =E6 | G10: =F10+1 | H10: =G10+1 | I10: =H10+1 | J10: =I10+1 | K10: =J10+1 | L10: =K10+1 | M10: =L10+1 | N10: =M10+1 | ... S10: =R10+1 | T10: Phillip Williams
A11: T2-001 | B11: EPIC-004 | C11: Design shopping cart database schema | D11: Phillip Williams | E11: 6 | F11: 6 | G11: 5 | H11: 3 | I11: 0 | J11: 0 | K11: 0 | L11: 0 | M11: 0 | N11: 0 | O11: 0 | P11: 0 | Q11: 0 | R11: 0 | S11: 0 | T11: Phillip Williams
A12: T2-002 | B12: EPIC-004 | C12: Create shopping cart API (add/remove/update) | D12: Phillip Williams | E12: 10 | F12: 10 | G12: 10 | H12: 8 | I12: 6 | J12: 3 | K12: 0 | L12: 0 | M12: 0 | N12: 0 | O12: 0 | P12: 0 | Q12: 0 | R12: 0 | S12: 0 | T12: Phillip Williams
A13: T2-003 | B13: EPIC-004 | C13: Build shopping cart UI component | D13: Phillip Williams | E13: 8 | F13: 8 | G13: 8 | H13: 8 | I13: 6 | J13: 4 | K13: 0 | L13: 0 | M13: 2 | N13: 0 | O13: 0 | P13: 0 | Q13: 0 | R13: 0 | S13: 0 | T13: Phillip Williams
A14: T2-004 | B14: EPIC-004 | C14: Implement checkout flow & order summary | D14: Phillip Williams | E14: 12 | F14: 12 | G14: 12 | H14: 12 | I14: 12 | J14: 10 | K14: 8 | L14: 5 | M14: 8 | N14: 6 | O14: 4 | P14: 2 | Q14: 0 | R14: 0 | S14: 0 | T14: Phillip Williams
A15: T2-005 | B15: EPIC-005 | C15: Integrate payment gateway (Stripe/PayPal) | D15: Ali Osman | E15: 14 | F15: 14 | G15: 14 | H15: 14 | I15: 14 | J15: 14 | K15: 12 | L15: 10 | M15: 14 | N15: 14 | O15: 12 | P15: 8 | Q15: 4 | R15: 0 | S15: 0 | T15: Tracy Pillow
A16: T2-006 | B16: EPIC-005 | C16: Build secure payment UI with validation | D16: Kyonna Robinson | E16: 8 | F16: 8 | G16: 8 | H16: 8 | I16: 8 | J16: 8 | K16: 8 | L16: 8 | M16: 6 | N16: 4 | O16: 2 | P16: 0 | Q16: 0 | R16: 0 | S16: 0 | T16: Tracy Pillow
A17: T2-007 | B17: EPIC-005 | C17: Implement payment confirmation & receipts | D17: Ali Osman | E17: 6 | F17: 6 | G17: 6 | H17: 6 | I17: 6 | J17: 6 | K17: 6 | L17: 6 | M17: 4 | N17: 2 | O17: 0 | P17: 0 | Q17: 0 | R17: 0 | S17: 0 | T17: Tracy Pillow
A18: T2-008 | B18: EPIC-006 | C18: Create order management system backend | D18: Nathan Horstmeier | E18: 10 | F18: 10 | G18: 10 | H18: 10 | I18: 10 | J18: 10 | K18: 10 | L18: 10 | M18: 8 | N18: 6 | O18: 4 | P18: 2 | Q18: 0 | R18: 0 | S18: 0 | T18: Nathan Horstmeier
A19: T2-009 | B19: EPIC-006 | C19: Build order tracking UI for customers | D19: Nathan Horstmeier | E19: 10 | F19: 10 | G19: 10 | H19: 10 | I19: 10 | J19: 10 | K19: 10 | L19: 10 | M19: 8 | N19: 6 | O19: 4 | P19: 2 | Q19: 0 | R19: 0 | S19: 0 | T19: Nathan Horstmeier
A20: T2-010 | B20: RETRO | C20: Weekly code integration check-ins (Sprint 1 improvement) | D20: Tracy Pillow | E20: 2 | F20: 2 | G20: 2 | H20: 2 | I20: 1 | J20: 1 | K20: 1 | L20: 1 | M20: 1 | N20: 0 | O20: 0 | P20: 0 | Q20: 0 | R20: 0 | S20: 0 | T20: Tracy Pillow
A21: T2-011 | B21: NONDEV | C21: Sprint 2 plan review/refinement meeting | D21: Tracy Pillow | E21: 2 | F21: 2 | G21: 0 | H21: 0 | I21: 0 | J21: 0 | K21: 0 | L21: 0 | M21: 0 | N21: 0 | O21: 0 | P21: 0 | Q21: 0 | R21: 0 | S21: 0 | T21: Tracy Pillow
A22: T2-012 | B22: NONDEV | C22: Team communication/status updates | D22: Tracy Pillow | E22: 2 | F22: 2 | G22: 2 | H22: 1 | I22: 1 | J22: 0 | K22: 0 | L22: 0 | M22: 0 | N22: 0 | O22: 0 | P22: 0 | Q22: 0 | R22: 0 | S22: 0 | T22: Tracy Pillow
A23: T2-013 | B23: NONDEV | C23: Git, ZIP organization, and submission prep | D23: Tracy Pillow | E23: 3 | F23: 3 | G23: 3 | H23: 3 | I23: 2 | J23: 1 | K23: 0 | L23: 0 | M23: 0 | N23: 0 | O23: 0 | P23: 0 | Q23: 0 | R23: 0 | S23: 0 | T23: Tracy Pillow
C24: Remaining units (actual) | E24: =SUM(E11:E23) | F24: =SUM(F11:F23) | G24: =SUM(G11:G23) | H24: =SUM(H11:H23) | I24: =SUM(I11:I23) | J24: =SUM(J11:J23) | K24: =SUM(K11:K23) | L24: =SUM(L11:L23) | ... S24: =SUM(S11:S23)
C25: Remaining units (ideal) | F25: =$E$24*(14-(F$9-1))/14 | G25: =$E$24*(14-(G$9-1))/14 | H25: =$E$24*(14-(H$9-1))/14 | I25: =$E$24*(14-(I$9-1))/14 | J25: =$E$24*(14-(J$9-1))/14 | K25: =$E$24*(14-(K$9-1))/14 | L25: =$E$24*(14-(L$9-1))/14 | M25: =$E$24*(14-(M$9-1))/14 | ... S25: =$E$24*(14-(S$9-1))/14
K30: 0 | L30: =SUM(E11:E20) | R30: 0 | S30: =SUM(L11:L20)
K31: 10 | L31: 0 | R31: 10 | S31: 0
A33: Actual completion note: EPIC-004 shopping cart tasks are assigned to Phillip Williams. Phillip is responsible for shopping cart schema/API/UI/checkout flow proof, screenshots, and final integration support for Sprint 2.

Sheet Sprint 1 Retrospective
A1: Sprint #1 Retrospective Summary Report
A3: Project: | B3: AceReads
A4: Sprint #: | B4: 1
A5: Sprint Duration: | B5: June 8 – June 21, 2026 (2 weeks)
A6: Sprint Goal: | B6: User Registration, Book Inventory & Search Functionality
A7: Date Completed: | B7: June 21, 2026
A9: WHAT WORKED WELL
A10: 1. All 13 sprint tasks were completed on time, achieving 100% completion rate across the team.
A11: 2. Core Sprint 1 deliverables — user registration, book inventory, and search — are functional and integrated.
A12: 3. Team members adapted well to shifting priorities; tasks were redistributed as needed and still delivered on schedule.
A13: 4. Sprint velocity of 104 story points establishes a strong baseline for planning future sprints.
A14: 5. Individual components developed independently came together successfully through integration work at the end of the sprint.
A16: WHAT DID NOT WORK WELL
A17: 1. Task ownership was not always clearly defined at the start of the sprint, requiring mid-sprint adjustments to workload distribution.
A18: 2. Team members joined and onboarded at different points in the sprint cycle, making it difficult to align everyone on scope and responsibilities from day one.
A19: 3. Each team member developed their piece independently without a shared communication rhythm, so integration work at the end required extra effort to reconcile differences.
A20: 4. Acceptance criteria in the backlog were not always specific enough, leading to some ambiguity about what "done" looked like for individual tasks.
A21: 5. Without regular check-ins, small blockers went unresolved longer than necessary and were only surfaced during weekly touchpoints.
A23: HOW THE TEAM WILL IMPROVE
A24: # | B24: Action Item | C24: Owner | D24: Target Date | E24: Status | F24: Expected Impact
A25: 1 | B25: Establish daily 15-min standup meetings (in-person or virtual) | C25: Scrum Master | D25: Sprint 2 Day 1 | E25: Scheduled | F25: Eliminates blocker buildup; ensures daily progress visibility
A26: 2 | B26: Create shared task board with clear ownership visible to all members | C26: Scrum Master | D26: Sprint 2 Day 1 | E26: In Progress | F26: Single source of truth for task ownership reduces confusion
A27: 3 | B27: Document onboarding checklist for any new team members added mid-project | C27: Product Owner | D27: Sprint 2 Day 3 | E27: Planned | F27: Reduces ramp-up time for future additions; ensures consistent process
A28: 4 | B28: Review and update task descriptions in backlog before each sprint | C28: Product Owner | D28: Before Sprint 3 | E28: Planned | F28: Clearer acceptance criteria reduces ambiguity and rework time
A29: 5 | B29: Set up team communication channel for real-time updates and questions | C29: Development Team | D29: Sprint 2 Day 1 | E29: Completed | F29: Real-time async communication reduces delays and gaps
A31: SPRINT METRICS SUMMARY
A32: Total Story Points Committed: | B32: =SUM('Sprint 1'!E11:E23)
A33: Story Points Completed: | B33: =B32
A34: Completion Rate: | B34: 100%
A35: Tasks Completed: | B35: 13 of 13
A36: Total Tasks: | B36: 13
A37: Sprint Velocity (pts/sprint): | B37: =B32
A39: TEAM PARTICIPATION
A40: Team Member | B40: Tasks Assigned | C40: Notes | D40: Hours (Est) | E40: Tasks Completed | F40: Sprint 1 Role
A41: Ali Osman | B41: =COUNTIF('Sprint 1'!D11:D23,A41) | C41: Delivered assigned tasks on schedule; contributed to Sprint 2 planning. | D41: 18 | E41: 2/2 | F41: Registration & Auth backend (T1-001, T1-002)
A42: Kyonna Robinson | B42: =COUNTIF('Sprint 1'!D11:D23,A42) | C42: Delivered UI components on schedule. | D42: 14 | E42: 2/2 | F42: UI development — Login page, search results page (T1-004, T1-011)
A43: Juana Rodriguez | B43: =COUNTIF('Sprint 1'!D11:D23,A43) | C43: Completed assigned backend and search tasks on schedule. | D43: 26 | E43: 3/3 | F43: Login system, search backend & functionality (T1-003, T1-008, T1-010)
A44: Nathan Horstmeier | B44: =COUNTIF('Sprint 1'!D11:D23,A44) | C44: Delivered all assigned tasks; supported integration and compilation of components. | D44: 46 | E44: 6/6 | F44: Book inventory, CRUD APIs, admin UI, search config, SSL, RBAC (T1-005 to T1-013)
A45: Phillip Williams | B45: =COUNTIF('Sprint 1'!D11:D23,A45) | C45: Onboarded to the project near end of Sprint 1; prepared for Sprint 2 contribution. | D45: 0 | E45: 0/0 | F45: Joined team end of Sprint 1; Sprint 2 contributor
A46: Tracy Pillow | B46: =COUNTIF('Sprint 1'!D11:D23,A46) | C46: Scrum Master — coordinated sprint planning, communication, and submission prep. | D46: 8 | E46: N/A | F46: Scrum Master / project coordination

Sheet Emergency Guide
A1: ACEREADS EMERGENCY SURVIVAL GUIDE - Complete These Tasks Yourself
A3: TODAY: Sunday June 21, 2026 | Sprint 1 Day 14 of 14 | DEADLINE DAY!
A4: TOTAL TIME NEEDED: 3-4 hours following this guide exactly
A5: STEP 0: INSTALL THESE FIRST (One-time setup - 30 minutes)
A7: # | B7: What to Install | C7: Why You Need It | D7: How to Get It | E7: Time
A8: 1 | B8: Node.js | C8: Runs JavaScript code | D8: Download from nodejs.org - click 'LTS' button, run installer, click Next until done | E8: 5 min
A9: 2 | B9: VS Code | C9: Write and edit code | D9: Download from code.visualstudio.com - run installer | E9: 5 min
A10: 3 | B10: Git | C10: Track code changes | D10: Download from git-scm.com - run installer, keep defaults | E10: 5 min
A11: 4 | B11: MySQL | C11: Database for storing data | D11: Download MySQL Community Server from mysql.com/downloads - remember your password! | E11: 10 min
A12: 5 | B12: Postman | C12: Test your APIs | D12: Download from postman.com - free account | E12: 5 min
A14: STEP 1: CREATE YOUR PROJECT FOLDER (15 minutes)
A16: Open VS Code, then open Terminal (View > Terminal). Type these commands one at a time, press Enter after each:
A18: COMMAND | B18: WHAT IT DOES
A19: mkdir acereads | B19: Creates a folder called 'acereads'
A20: cd acereads | B20: Goes into that folder
A21: npm init -y | B21: Creates package.json (project settings file)
A22: npm install express mysql2 bcrypt jsonwebtoken cors dotenv | B22: Installs the tools you need
A23: mkdir src | B23: Creates src folder for your code
A24: mkdir src/routes src/models src/middleware src/controllers | B24: Creates subfolders to organize code
A25: touch src/app.js (Mac) OR type nul > src\app.js (Windows) | B25: Creates your main app file
A27: STEP 2: CREATE YOUR DATABASE (20 minutes) - THIS COMPLETES T1-001, T1-005, T2-001
A29: Open MySQL Workbench (installed with MySQL). Click the Local instance to connect. Then copy/paste this entire block:
A31: -- COPY EVERYTHING BELOW THIS LINE --
A32: CREATE DATABASE IF NOT EXISTS acereads;
A33: USE acereads;
A35: -- Users table (for login/registration)
A36: CREATE TABLE users (
A37: id INT AUTO_INCREMENT PRIMARY KEY,
A38: email VARCHAR(255) UNIQUE NOT NULL,
A39: password VARCHAR(255) NOT NULL,
A40: first_name VARCHAR(100),
A41: last_name VARCHAR(100),
... A329: In VS Code terminal, make sure you're in the acereads folder, then type:
A331: node src/server.js | B331: Starts your application
A333: You should see: 'AceReads server running on http://localhost:3000'
A335: TO TEST IT WORKS:
A336: Open your web browser and go to: http://localhost:3000/api/health
A337: You should see: { "status": "AceReads API is running!" }
A339: CONGRATULATIONS! Your backend is working!
A341: STEP 9: TEST YOUR APIs WITH POSTMAN (10 min)
...

Sheet Quick Copy
A1: QUICK COPY - Select each section and paste into separate files
A3: Instructions: For each file below, select from START to END, copy, paste into Notepad, save with filename shown.
A5: FILE 1: database_setup.sql
A6: Location: Emergency Guide sheet, rows 31-97
A7: Save as: acereads/database_setup.sql
A9: FILE 2: app.js
A10: Location: Emergency Guide sheet, rows 103-122
A11: Save as: acereads/src/app.js
A13: FILE 3: auth.js
A14: Location: Emergency Guide sheet, rows 128-180
A15: Save as: acereads/src/routes/auth.js
A17: FILE 4: books.js
... A108: Rename to CS492_GP2.ZIP and submit!

Sheet Submission Alignment
A1: AceReads Sprint 2 Week 1 Rubric Alignment / Final ZIP Checklist
A2: Rubric Item | B2: Points | C2: Workbook / Package Evidence | D2: Status
A3: Communication with the Group | B3: 20 | C3: Sprint 2 rows 20:23 document code integration check-ins, Sprint 2 plan review, team communication/status updates, submission coordination, and updated team communication context including Phillip Williams rejoining after a family emergency. | D3: Ready
A4: Sprint 2 Planning | B4: 30 | C4: Sprint 2 sheet is refined from Sprint 1 progress; column D keeps planned responsibility and column T documents actual completed-by credit; Package Contents confirms the completed app structure, setup path, and supporting docs. | D4: Ready
A5: Sprint 2 - Week 1 Hours Tracking | B5: 30 | C5: Sprint 2 sheet columns F:L show Week 1 remaining hours for every Sprint 2 development and non-development task. | D5: Ready
A6: Non Development Activities | B6: 20 | C6: Sprint 2 rows 20:23 include weekly integration check-ins, planning/refinement, team communication, and Git/ZIP organization/submission prep. | D6: Ready
A7: Organization | B7: 15 | C7: Submit CS492_GP2.ZIP containing the complete acereads folder, Sprint Planning workbook, Group Project Document, and docs listed on Package Contents. | D7: Ready
A8: Professional Language | B8: 10 | C8: Checklist wording is cleaned up; proofread the Word Project Document before final upload. | D8: Ready
A9: Total Possible Points | B9: 125 | C9: All rubric components accounted for in the workbook/package evidence. | D9: Ready
A11: Final ZIP should be named: | B11: CS492_GP2.ZIP | D11: Required
A12: Include in ZIP: | B12: 1 | C12: Sprint_Planning.xlsx / completed Sprint Planning Document with Sprint 2 Week 1 hours tracked | D12: Required
A13: Include in ZIP: | B13: 2 | C13: Group Project Document / Word document updated for Sprint 2 planning, progress, communication, non-development activities, and application package summary | D13: Required
A14: Include in ZIP: | B14: 3 | C14: Complete acereads folder with backend, frontend, SQLite database setup, package files, and documentation | D14: Recommended
A15: Include in ZIP: | B15: 4 | C15: README, SETUP, API documentation, project proposal, and quick reference documents | D15: Recommended
A16: Before submitting: | B16: 1 | C16: Open the ZIP and confirm actual files are inside, not shortcuts only. | D16: Do this
A17: Before submitting: | B17: 2 | C17: Confirm Sprint 2 columns F:L contain Week 1 hours/remaining work for every task. | D17: Do this
A18: Before submitting: | B18: 3 | C18: Confirm non-development activities are visible in Sprint 2 rows 20:23 and discussed in the Project Document. | D18: Do this
A19: Before submitting: | B19: 4 | C19: Upload only the final CS492_GP2.ZIP file. | D19: Do this

Sheet Package Contents
A1: AceReads Package Contents / Submission Evidence
A2: Category | B2: Included Items | C2: Status
A3: Backend | B3: backend/server.js; backend/package.json; SQLite database auto-created on startup; Express REST API with CRUD operations | C3: Included
A4: Frontend | B4: frontend/index.html; frontend/styles.css; frontend/app.js; responsive vanilla JavaScript UI | C4: Included
A5: Documentation | B5: docs/README.md; SETUP.md; API_DOCUMENTATION.md; PROJECT_PROPOSAL.md; QUICK_REFERENCE.md | C5: Included
A6: Setup Steps | B6: cd acereads/backend; npm install; npm start; open frontend/index.html | C6: Ready
A7: Features | B7: Books, customers, orders, inventory, reports, dashboard, inventory history, error handling | C7: Included
A8: Database | B8: SQLite with books, customers, orders, order_items, and inventory_history tables | C8: Included
A9: Technical Stack | B9: Node.js, Express.js, SQLite3, CORS, HTML5, CSS3, vanilla JavaScript, Fetch API | C9: Included
A10: Submission Folder | B10: Submit the entire acereads folder plus Sprint Planning Document and Group Project Document | C10: Required
A11: Final Status | B11: Complete project package is ready for ZIP review and assignment submission | C11: Ready

Sheet Emergency Task Guide
A1: ACEREADS EMERGENCY TASK GUIDE - Sprint 1 Deadline Support
A2: Sprint 1 ends Sunday June 21. Submit by deadline. Partial work is better than no work.
A4: 📅 WEEKEND MEETING - When can you meet?
A5: React to vote: | B5: 🅰️ Saturday June 20 - Morning (9am-12pm) | C5: 🅱️ Saturday June 20 - Afternoon (1pm-5pm) | D5: 🇨 Sunday June 21 - Morning (9am-12pm) | E5: 🇩 Sunday June 21 - Afternoon (1pm-5pm)
A6: Message to team:
A8: What to submit
A9: 🚨 PRIORITY HELP NEEDED: Kyonna + Phillip
A10: Team support note | B10: Kyonna Robinson and Phillip Williams need the most help because they have not submitted anything yet and may not know how to complete their assigned work. Focus first on getting them simple working files or screenshots they can submit.
A11: Kyonna rescue plan | B11: Kyonna Robinson - PRIORITY HELP NEEDED | C11: 1) Install VS Code. 2) Create frontend folder. 3) Save the provided HTML/CSS/JS files. 4) Open index.html in browser. 5) Screenshot registration/login form and validation error. | D11: Beginner path: copy the provided frontend files, open index.html in a browser, confirm the form appears, test password validation, then screenshot the result. Ask Tracy/team for help if any file does not open. | E11: Submit frontend files + screenshots
A12: Phillip rescue plan | B12: Phillip Williams - PRIORITY HELP NEEDED | C12: 1) Install Node.js + VS Code. 2) Run npm init -y. 3) Install express cors bcrypt jsonwebtoken. 4) Save backend files. 5) Run node src/server.js. 6) Test /api/health, /api/books, /api/books/search, and /api/cart. | D12: Beginner path: copy the provided backend files, run npm install, start the server, then screenshot /api/health and any working search/cart/security endpoint. Partial API screenshots are acceptable. | E12: Submit code + API screenshots
A13: What helpers should do | B13: Do not wait for perfect work. Pair with Kyonna and Phillip, copy/paste the provided starter code into files, help them run it, and collect screenshots. Partial working proof is acceptable for final submission. | C13: If they are stuck, have them paste the code into Discord and explain what they tried. The team can combine and clean it before final upload. | D13: Priority: Kyonna first for frontend, Phillip second for backend/cart/security | E13: Discord update + screenshots
A14: Emergency Discord message
A18: ⏰ Timeline Reminder
A19: Day | B19: Date | C19: Status
A20: Today | B20: Wed June 17 | C20: Day 10
A21: Thu | B21: 46191 | C21: Day 11
A22: Fri | B22: 46192 | C22: Day 12
A23: Sat | B23: 46193 | C23: Day 13 - Meeting?
A24: Sun | B24: 46194 | C24: Day 14 - DEADLINE
A26: Install these first | B26: Why you need it | C26: How to install | D26: Who needs it | E26: Proof to submit
A27: Node.js LTS | B27: Runs backend JavaScript server and installs packages | C27: Download from nodejs.org, run installer, verify: node -v and npm -v | D27: Ali, Kyonna, Nathan, Phillip | E27: Terminal screenshot
A28: VS Code | B28: Edit code files | C28: Download from code.visualstudio.com and install defaults | D28: Everyone | E28: Project screenshot
A29: Git | B29: Track/share code if available | C29: Download from git-scm.com and install defaults | D29: Everyone | E29: Optional git --version screenshot
A30: MySQL or SQLite | B30: Stores users/books/cart data | C30: Use MySQL Workbench if installed; SQLite is acceptable for quick proof | D30: Ali, Nathan, Phillip | E30: Screenshot database/tables
A31: Postman or Browser | B31: Test API endpoints | C31: Install Postman or use browser for GET endpoints | D31: Ali, Nathan, Phillip | E31: API response screenshot
A33: Quick Task Reference | B33: Owner | C33: What needs to be done | D33: How to complete | E33: What to submit
A34: T1-001 User registration API endpoint | B34: Ali | C34: Create POST /api/auth/register that accepts email/password/name and saves user | D34: Use Express route; validate fields; hash password; insert user | E34: auth.js + register screenshot
A35: T1-002 Login/authentication system | B35: Ali | C35: Create POST /api/auth/login | D35: Find user by email; compare bcrypt password; return JSON success/token | E35: auth.js + login screenshot
A36: T1-005 Database schema setup | B36: Ali | C36: Create users and books database tables | D36: Run database_setup.sql below | E36: SQL file + table screenshot
A37: T1-006 Password encryption + session management | B37: Ali | C37: Use bcrypt and JWT/session token | D37: Install bcrypt jsonwebtoken; hash on register; verify on login; return token | E37: Code + token screenshot
A38: T1-004 Input validation for registration | B38: Kyonna Robinson - PRIORITY HELP NEEDED | C38: Validate email/password rules | D38: Beginner path: copy the provided frontend files, open index.html in a browser, confirm the form appears, test password validation, then screenshot the result. Ask Tracy/team for help if any file does not open. | E38: app.js + validation screenshot
... A44: Phillip support tasks | B44: Phillip Williams - PRIORITY HELP NEEDED | C44: Take any Nathan task not already posted above, plus integration support | D44: Beginner path: copy the provided backend files, run npm install, start the server, then screenshot /api/health and any working search/cart/security endpoint. Partial API screenshots are acceptable. | E44: Files/screenshots + Discord update
A46: Ready-to-submit: database_setup.sql
A47: Code | B47: CREATE DATABASE IF NOT EXISTS acereads; USE acereads; CREATE TABLE IF NOT EXISTS users ( id INT AUTO_INCREMENT PRIMARY KEY, email VARCHAR(255) UNIQUE NOT NULL, password VARCHAR(255) NOT NULL, first_name VARCHAR(100), last_name VARCHAR(100), created_at TIMESTAMP DEFAULT CURRENT_TIMESTAMP ); CREATE TABLE IF NOT EXISTS books ( id INT AUTO_INCREMENT PRIMARY KEY, isbn VARCHAR(30) UNIQUE, title VARCHAR(255) NOT NULL, author VARCHAR(255) NOT NULL, price DECIMAL(10,2) DEFAULT 0.00, quantity INT DEFAULT 0, category VARCHAR(100), created_at TIMESTAMP DEFAULT CURRENT_TIMESTAMP ); INSERT INTO books (isbn,title,author,price,quantity,category) VALUES ('978000000001','Sample Book One','Demo Author',19.99,10,'Fiction'), ('978000000002','Sample Book Two','Demo Author',24.99,5,'Education');
A49: Install/run commands
A50: Commands | B50: npm init -y npm install express mysql2 bcrypt jsonwebtoken cors dotenv mkdir src mkdir src/routes node src/server.js
A52: Ready-to-submit: src/server.js
A53: Code | B53: const express = require('express'); const cors = require('cors'); const authRoutes = require('./routes/auth'); const bookRoutes = require('./routes/books'); const app = express(); app.use(cors()); app.use(express.json()); app.get('/api/health', (req, res) => res.json({ status: 'AceReads API is running' })); app.use('/api/auth', authRoutes); app.use('/api/books', bookRoutes); app.listen(3000, () => console.log('AceReads server running on http://localhost:3000'));
A55: Ready-to-submit: src/routes/auth.js
A56: Code | B56: const express = require('express'); const bcrypt = require('bcrypt'); const jwt = require('jsonwebtoken'); const router = express.Router(); const users = []; // quick in-memory proof; replace with database when ready function strongPassword(password) { return password && password.length >= 8 && /[A-Z]/.test(password) && /[0-9]/.test(password) && /[^A-Za-z0-9]/.test(password); } router.post('/register', async (req, res) => { const { email, password, firstName, lastName } = req.body; if (!email || !password) return res.status(400).json({ error: 'Email and password are required' }); if (!strongPassword(password)) return res.status(400).json({ error: 'Password must be 8+ chars with uppercase, number, and special character' }); if (users.find(u => u.email === email)) return res.status(400).json({ error: 'Email already registered' }); const hashedPassword = await bcrypt.hash(password, 10); const user = { id: users.length + 1, email, password: hashedPassword, firstName, lastName }; users.push(user); res.status(201).json({ message: 'Registration successful', userId: user.id }); }); router.post('/login', async (req, res) => { const { email, password } = req.body; const user = users.find(u => u.email === email); if (!user) return res.status(401).json({ error: 'Invalid email or password' }); const valid = await bcrypt.compare(password, user.password); if (!valid) return res.status(401).json({ error: 'Invalid email or password' }); const token = jwt.sign({ userId: user.id, email: user.email }, 'dev-secret', { expiresIn: '30m' }); res.json({ message: 'Login successful', token }); }); module.exports = router;
...
