Workbook

Sheet Introduction
A2: Project Name
A6: What is this? | B6: This workbook is meant to help manage and piroritize the user stories and features using scrum.
A11: How to use and read this document? | B11: Before project start: The product owner is responsible for managing and maintaining the product backlog of user stories.
B12: Before each sprint: The vendor will break down the user stories into tasks.
A15: Notes | B15: Cells that you can edit have a blue background.
B16: Sprints are assumed to be 2 weeks long (10 working days)/
A18: Licence | B18: This work is licensed under a Creative Commons Attribution-Share Alike 3.0 Unported License.
A23: Origins | B23: This work is inspired by the Scrum Template published by Nicolas Martignole on his "Touilleur Express" blog. Adapted by Olivier Gérardin.

Sheet Product backlog
A2: AceReads - Bookstore Management System
B4: Organizations | C4: Ana's Anomalous Anthologies
B5: Project | C5: AceReads
B6: Product Owner | C6: Juana Rodriguez
B7: Scrum Master | C7: Tracy Pillow
B8: Development Team | C8: Ali Osman, Kyonna Robinson, Juana Rodriguez, Nathan Horstmeier, Phillip Williams
A10: Story ID | B10: Title | C10: Description | D10: s | E10: Priority # | F10: Sprint # | G10: Responsibility
A11: EPIC-001 | B11: User Registration & Authentication | C11: As a user, I want to register and securely log into the system so that I can access personalized features and my account information is protected. | D11: 1. Users can register with email, password (min 8 chars, 1 uppercase, 1 number, 1 special char) 2. Email verification is required before account activation 3. Password is encrypted using industry-standard hashing (bcrypt) 4. Users can log in with valid credentials 5. Failed login attempts are limited (max 5) with account lockout 6. Password reset functionality via secure email link 7. Session timeout after 30 minutes of inactivity | E11: 1 | F11: 1 | G11: Development Team
A12: EPIC-002 | B12: Book Inventory Management | C12: As a store manager, I want to manage the book inventory so that I can add, update, and track all books in the system with accurate stock levels. | D12: 1. Admin can add new books with ISBN, title, author, price, quantity, category, publisher, publication date 2. Admin can update existing book information 3. Admin can delete books (soft delete to maintain history) 4. System displays real-time stock levels 5. Low stock alerts triggered when quantity falls below threshold 6. Bulk import of books via CSV/Excel file 7. Book images can be uploaded and displayed 8. Search and filter books by multiple criteria | E12: 1 | F12: 1 | G12: Development Team
A13: EPIC-003 | B13: Book Search & Catalog Browsing | C13: As a customer, I want to search and browse books so that I can easily find books I'm interested in purchasing. | D13: 1. Search by title, author, ISBN, or keyword 2. Filter results by category, price range, availability, rating 3. Sort results by relevance, price, date, popularity 4. Display book details including description, reviews, ratings 5. Search results load within 2 seconds 6. Auto-suggest/autocomplete functionality 7. Browse by categories and subcategories 8. Recently viewed books history | E13: 2 | F13: 1 | G13: Development Team
A14: EPIC-004 | B14: Shopping Cart & Checkout Process | C14: As a customer, I want to add books to a shopping cart and complete purchases so that I can buy multiple books in a single transaction. | D14: 1. Add/remove books from cart 2. Update quantities in cart 3. Cart persists across sessions for logged-in users 4. Display itemized cart with subtotal, taxes, shipping 5. Apply discount codes/coupons 6. Multiple shipping address options 7. Order summary before final confirmation 8. Email confirmation sent upon successful order 9. Cart abandonment recovery emails | E14: 1 | F14: 2 | G14: Development Team
A15: EPIC-005 | B15: Secure Payment Processing | C15: As a customer, I want to make secure payments so that my financial information is protected and I can complete transactions safely. | D15: 1. Integration with PCI-DSS compliant payment gateway 2. Support multiple payment methods (credit/debit cards, PayPal, digital wallets) 3. Card details are never stored on local servers 4. SSL/TLS encryption for all payment transactions 5. Payment confirmation and receipt generation 6. Refund processing capability 7. Transaction logging for audit purposes 8. Fraud detection mechanisms in place | E15: 1 | F15: 2 | G15: Development Team
A16: EPIC-006 | B16: Order Management System | C16: As a store manager, I want to manage customer orders so that I can track order status, process shipments, and handle returns efficiently. | D16: 1. View all orders with filtering by status, date, customer 2. Update order status (pending, processing, shipped, delivered, cancelled) 3. Generate shipping labels and tracking numbers 4. Send automated status update notifications to customers 5. Process returns and refunds 6. Order history maintained for minimum 7 years 7. Generate order reports and analytics 8. Handle partial shipments | E16: 2 | F16: 2 | G16: Development Team
A17: EPIC-007 | B17: Customer Account Management | C17: As a customer, I want to manage my account profile so that I can update my information, view order history, and manage preferences. | D17: 1. View and edit personal information 2. Manage multiple shipping/billing addresses 3. View complete order history 4. Track current orders in real-time 5. Manage wishlist/favorites 6. Set communication preferences 7. View and manage saved payment methods (tokenized) 8. Download invoices/receipts 9. Account deletion option (GDPR compliance) | E17: 2 | F17: 3 | G17: Development Team
A18: EPIC-008 | B18: Book Reviews & Ratings System | C18: As a customer, I want to read and write book reviews so that I can make informed purchasing decisions and share my opinions with other readers. | D18: 1. Submit star ratings (1-5) for purchased books 2. Write text reviews with character limit 3. Edit or delete own reviews 4. View average ratings and total review count 5. Sort reviews by date, rating, helpfulness 6. Mark reviews as helpful 7. Admin moderation of inappropriate content 8. Verified purchase badge on reviews | E18: 3 | F18: 3 | G18: Development Team
A19: EPIC-009 | B19: Reporting & Business Analytics | C19: As a store manager, I want to access reports and analytics so that I can make data-driven business decisions and monitor store performance. | D19: 1. Sales reports by period, category, author 2. Inventory reports with stock levels and turnover 3. Customer analytics (demographics, behavior) 4. Revenue and profit margin reports 5. Best-selling books reports 6. Export reports to PDF, Excel, CSV 7. Dashboard with key performance indicators 8. Customizable date ranges for all reports 9. Scheduled automated report generation | E19: 2 | F19: 4 | G19: Development Team
A20: EPIC-010 | B20: Security & Data Protection | C20: As a system administrator, I want to ensure comprehensive security measures so that customer data is protected and the system is secure from threats. | D20: 1. Role-based access control (RBAC) implemented 2. All sensitive data encrypted at rest and in transit 3. Regular automated security vulnerability scanning 4. Audit logs for all administrative actions 5. IP-based access restrictions for admin panel 6. Two-factor authentication (2FA) for admin accounts 7. Regular automated backups with encryption 8. GDPR and data privacy compliance 9. SQL injection and XSS prevention measures 10. Rate limiting to prevent DDoS attacks | E20: 1 | F20: 1 | G20: Development Team
A21: EPIC-011 | B21: Notifications & Communication System | C21: As a customer, I want to receive relevant notifications so that I stay informed about my orders, promotions, and new arrivals. | D21: 1. Email notifications for order confirmations, shipping, delivery 2. Promotional email campaigns with opt-in/opt-out 3. New arrival notifications for favorite categories/authors 4. Back-in-stock notifications 5. Price drop alerts for wishlist items 6. SMS notifications option for order updates 7. In-app notification center 8. Unsubscribe option in all communications | E21: 3 | F21: 4 | G21: Development Team
A22: EPIC-012 | B22: Administrative Dashboard | C22: As an administrator, I want a centralized dashboard so that I can efficiently manage all aspects of the bookstore operations. | D22: 1. Overview of daily/weekly/monthly sales 2. Pending orders requiring attention 3. Low stock alerts prominently displayed 4. Recent customer activity feed 5. Quick access to all management modules 6. System health and performance metrics 7. User management capabilities 8. Content management for banners/promotions 9. Responsive design for mobile access | E22: 2 | F22: 3 | G22: Development Team
... A25: EPIC-015 | B25: Mobile-Responsive Design | C25: As a customer, I want to access the bookstore from any device so that I can browse and purchase books conveniently from my smartphone or tablet. | D25: 1. Fully responsive design across all screen sizes 2. Touch-friendly navigation and buttons 3. Optimized images for mobile bandwidth 4. Mobile-specific features (tap to call, maps integration) 5. Fast loading times on mobile networks (<3 seconds) 6. Consistent experience across iOS and Android browsers 7. Mobile checkout optimization 8. Progressive Web App (PWA) capabilities | E25: 2 | F25: 4 | G25: Development Team

Sheet Sprint 1
A2: =CONCATENATE("Sprint #",E5, "Tracking Sheet") -> Sprint #1Tracking Sheet
C4: Project | E4: AceReads
C5: Sprint # | E5: 1
C6: Start date | E6: 46181
D7: Total Team Members | E7: 5
F8: week 1 | M8: week 2
F9: 1 | G9: 2 | H9: 3 | I9: 4 | J9: 5 | K9: 6 | L9: 7 | M9: 8 | N9: 9 | O9: 10 | P9: 11 | Q9: 12 | R9: 13 | S9: 14
A10: Task ID | B10: Story ID | C10: Description | D10: Responsibility | E10: Initial estimate | F10: =E6 -> 46181 | G10: =F10+1 -> 46182 | H10: =G10+1 -> 46183 | I10: =H10+1 -> 46184 | J10: =I10+1 -> 46185 | K10: =J10+1 -> 46186 | L10: =K10+1 -> 46187 | M10: =L10+1 -> 46188 | N10: =M10+1 -> 46189 | ... S10: =R10+1 -> 46194
A11: T1-001 | B11: EPIC-001 | C11: Design & implement user registration (DB, API, UI) | D11: Ali Osman | E11: 12 | F11: 12 | G11: 10 | H11: 8 | I11: 5 | J11: 0 | K11: 0 | L11: 0 | M11: 0 | N11: 0 | O11: 0 | P11: 0 | Q11: 0 | R11: 0 | S11: 0
A12: T1-002 | B12: EPIC-001 | C12: Implement password encryption & validation | D12: Ali Osman | E12: 6 | F12: 6 | G12: 5 | H12: 3 | I12: 0 | J12: 0 | K12: 0 | L12: 0 | M12: 0 | N12: 0 | O12: 0 | P12: 0 | Q12: 0 | R12: 0 | S12: 0
A13: T1-003 | B13: EPIC-001 | C13: Create login system with session management | D13: Juana Rodriguez | E13: 10 | F13: 10 | G13: 10 | H13: 10 | I13: 8 | J13: 5 | K13: 2 | L13: 0 | M13: 0 | N13: 0 | O13: 0 | P13: 0 | Q13: 0 | R13: 0 | S13: 0
A14: T1-004 | B14: EPIC-001 | C14: Build login/registration UI with error handling | D14: Kyonna Robinson | E14: 8 | F14: 8 | G14: 8 | H14: 8 | I14: 6 | J14: 4 | K14: 2 | L14: 0 | M14: 0 | N14: 0 | O14: 0 | P14: 0 | Q14: 0 | R14: 0 | S14: 0
A15: T1-005 | B15: EPIC-002 | C15: Design book inventory database schema | D15: Nathan Horstmeier | E15: 6 | F15: 6 | G15: 6 | H15: 6 | I15: 6 | J15: 6 | K15: 6 | L15: 4 | M15: 2 | N15: 0 | O15: 0 | P15: 0 | Q15: 0 | R15: 0 | S15: 0
A16: T1-006 | B16: EPIC-002 | C16: Create CRUD APIs for book management | D16: Nathan Horstmeier | E16: 12 | F16: 12 | G16: 12 | H16: 12 | I16: 12 | J16: 12 | K16: 10 | L16: 8 | M16: 6 | N16: 4 | O16: 2 | P16: 0 | Q16: 0 | R16: 0 | S16: 0
A17: T1-007 | B17: EPIC-002 | C17: Build admin book management interface | D17: Nathan Horstmeier | E17: 10 | F17: 10 | G17: 10 | H17: 10 | I17: 10 | J17: 10 | K17: 10 | L17: 10 | M17: 8 | N17: 6 | O17: 4 | P17: 2 | Q17: 0 | R17: 0 | S17: 0
A18: T1-008 | B18: EPIC-003 | C18: Implement book search & filtering backend | D18: Juana Rodriguez | E18: 6 | F18: 6 | G18: 6 | H18: 6 | I18: 6 | J18: 6 | K18: 6 | L18: 6 | M18: 6 | N18: 6 | O18: 0 | P18: 0 | Q18: 0 | R18: 0 | S18: 0
A19: T1-009 | B19: EPIC-003 | C19: Configure security (SSL, RBAC, input validation) | D19: Nathan Horstmeier | E19: 8 | F19: 8 | G19: 8 | H19: 8 | I19: 8 | J19: 8 | K19: 8 | L19: 8 | M19: 8 | N19: 8 | O19: 6 | P19: 4 | Q19: 2 | R19: 0 | S19: 0
A20: T1-010 | B20: EPIC-003 | C20: Implement book search functionality | D20: Juana Rodriguez | E20: 10 | F20: 10 | G20: 10 | H20: 10 | I20: 10 | J20: 10 | K20: 10 | L20: 10 | M20: 10 | N20: 8 | O20: 0 | P20: 0 | Q20: 0 | R20: 0 | S20: 0
A21: T1-011 | B21: EPIC-003 | C21: Build search results UI with filters | D21: Kyonna Robinson | E21: 6 | F21: 6 | G21: 6 | H21: 6 | I21: 6 | J21: 6 | K21: 6 | L21: 6 | M21: 6 | N21: 6 | O21: 6 | P21: 4 | Q21: 2 | R21: 0 | S21: 0
A22: T1-012 | B22: EPIC-010 | C22: Implement SSL/TLS security configuration | D22: Nathan Horstmeier | E22: 4 | F22: 4 | G22: 4 | H22: 4 | I22: 4 | J22: 4 | K22: 4 | L22: 4 | M22: 4 | N22: 4 | O22: 4 | P22: 4 | Q22: 2 | R22: 0 | S22: 0
A23: T1-013 | B23: EPIC-010 | C23: Set up role-based access control (RBAC) | D23: Nathan Horstmeier | E23: 6 | F23: 6 | G23: 6 | H23: 6 | I23: 6 | J23: 6 | K23: 6 | L23: 6 | M23: 6 | N23: 6 | O23: 6 | P23: 4 | Q23: 2 | R23: 0 | S23: 0
C25: Remaining units (actual) | E25: 104 | F25: =SUM(F11:F24) -> 104 | G25: =SUM(G11:G24) -> 101 | H25: =SUM(H11:H24) -> 97 | I25: =SUM(I11:I24) -> 87 | J25: =SUM(J11:J24) -> 77 | K25: =SUM(K11:K24) -> 70 | L25: =SUM(L11:L24) -> 62 | M25: =SUM(M11:M24) -> 56 | ... S25: =SUM(S11:S24) -> 0
C26: Remaining units (ideal) | F26: =SUM($E$11:$E$24) -> 104 | G26: =F26-($E$25/14) -> 96.571429 | H26: =G26-($E$25/14) -> 89.142857 | I26: =H26-($E$25/14) -> 81.714286 | J26: =I26-($E$25/14) -> 74.285714 | K26: =J26-($E$25/14) -> 66.857143 | L26: =K26-($E$25/14) -> 59.428571 | M26: =L26-($E$25/14) -> 52 | N26: =M26-($E$25/14) -> 44.571429 | ... S26: =R26-($E$25/14) -> 7.4285714

Sheet Sprint 2
A2: =CONCATENATE("Sprint #",E5, "Tracking Sheet") -> Sprint #2Tracking Sheet
C4: Project | E4: AceReads
C5: Sprint # | E5: 2
C6: Start date | E6: 46188
D7: Total Team Members | E7: 5
F8: week 1 | M8: week 2
F9: 1 | G9: 2 | H9: 3 | I9: 4 | J9: 5 | K9: 6 | L9: 7 | M9: 8 | N9: 9 | O9: 10 | P9: 11 | Q9: 12 | R9: 13 | S9: 14
A10: Task ID | B10: Story ID | C10: Description | D10: Responsibility | E10: Initial estimate | F10: =E6 -> 46188 | G10: =F10+1 -> 46189 | H10: =G10+1 -> 46190 | I10: =H10+1 -> 46191 | J10: =I10+1 -> 46192 | K10: =J10+1 -> 46193 | L10: =K10+1 -> 46194 | M10: =L10+1 -> 46195 | N10: =M10+1 -> 46196 | ... S10: =R10+1 -> 46201
A11: T2-001 | B11: EPIC-004 | C11: Design shopping cart database schema | D11: Ali Osman | E11: 6 | F11: 6 | G11: 5 | H11: 3 | I11: 0 | J11: 0 | K11: 0 | L11: 0 | M11: 0 | N11: 0 | O11: 0 | P11: 0 | Q11: 0 | R11: 0 | S11: 0
A12: T2-002 | B12: EPIC-004 | C12: Create shopping cart API (add/remove/update) | D12: Phillip Williams | E12: 10 | F12: 10 | G12: 10 | H12: 8 | I12: 6 | J12: 3 | K12: 0 | L12: 0 | M12: 0 | N12: 0 | O12: 0 | P12: 0 | Q12: 0 | R12: 0 | S12: 0
A13: T2-003 | B13: EPIC-004 | C13: Build shopping cart UI component | D13: Kyonna Robinson | E13: 8 | F13: 8 | G13: 8 | H13: 8 | I13: 6 | J13: 4 | K13: 0 | L13: 0 | M13: 0 | N13: 0 | O13: 0 | P13: 0 | Q13: 0 | R13: 0 | S13: 0
A14: T2-004 | B14: EPIC-004 | C14: Implement checkout flow & order summary | D14: Ali Osman | E14: 12 | F14: 12 | G14: 12 | H14: 12 | I14: 12 | J14: 10 | K14: 8 | L14: 5 | M14: 2 | N14: 0 | O14: 0 | P14: 0 | Q14: 0 | R14: 0 | S14: 0
A15: T2-005 | B15: EPIC-005 | C15: Integrate payment gateway (Stripe/PayPal) | D15: Ali Osman | E15: 14 | F15: 14 | G15: 14 | H15: 14 | I15: 14 | J15: 14 | K15: 12 | L15: 10 | M15: 8 | N15: 5 | O15: 2 | P15: 0 | Q15: 0 | R15: 0 | S15: 0
A16: T2-006 | B16: EPIC-005 | C16: Build secure payment UI with validation | D16: Kyonna Robinson | E16: 8 | F16: 8 | G16: 8 | H16: 8 | I16: 8 | J16: 8 | K16: 8 | L16: 8 | M16: 6 | N16: 4 | O16: 2 | P16: 0 | Q16: 0 | R16: 0 | S16: 0
A17: T2-007 | B17: EPIC-005 | C17: Implement payment confirmation & receipts | D17: Ali Osman | E17: 6 | F17: 6 | G17: 6 | H17: 6 | I17: 6 | J17: 6 | K17: 6 | L17: 6 | M17: 6 | N17: 6 | O17: 4 | P17: 2 | Q17: 0 | R17: 0 | S17: 0
A18: T2-008 | B18: EPIC-006 | C18: Create order management system backend | D18: Nathan Horstmeier | E18: 10 | F18: 10 | G18: 10 | H18: 10 | I18: 10 | J18: 10 | K18: 10 | L18: 10 | M18: 10 | N18: 8 | O18: 6 | P18: 4 | Q18: 2 | R18: 0 | S18: 0
A19: T2-009 | B19: EPIC-006 | C19: Build order tracking UI for customers | D19: Nathan Horstmeier | E19: 10 | F19: 10 | G19: 10 | H19: 10 | I19: 10 | J19: 10 | K19: 10 | L19: 10 | M19: 10 | N19: 8 | O19: 6 | P19: 4 | Q19: 2 | R19: 0 | S19: 0
S20: 0
C21: Remaining units (actual) | E21: =SUM(E11:E20) -> 84 | F21: =SUM(F11:F20) -> 84 | G21: =SUM(G11:G20) -> 83 | H21: =SUM(H11:H20) -> 79 | I21: =SUM(I11:I20) -> 72 | J21: =SUM(J11:J20) -> 65 | K21: =SUM(K11:K20) -> 54 | L21: =SUM(L11:L20) -> 49 | ... S21: =SUM(S11:S20) -> 0
C22: Remaining units (ideal) | F22: =SUM($E$11:$E$20) -> 84 | G22: =F22-($E$21/14) -> 78 | H22: =G22-($E$21/14) -> 72 | I22: =H22-($E$21/14) -> 66 | J22: =I22-($E$21/14) -> 60 | K22: =J22-($E$21/14) -> 54 | L22: =K22-($E$21/14) -> 48 | M22: =L22-($E$21/14) -> 42 | N22: =M22-($E$21/14) -> 36 | ... S22: =R22-($E$21/14) -> 6
K27: 0 | L27: =SUM(E11:E20) -> 84 | R27: 0 | S27: =SUM(L11:L20) -> 49
K28: 10 | L28: 0 | R28: 10 | S28: 0

Sheet Emergency Guide
A1: ACEREADS EMERGENCY SURVIVAL GUIDE - Complete These Tasks Yourself
A3: TODAY: Wednesday June 17, 2026 | Sprint 1 Day 10 of 14 | Sprint 2 Day 3 of 14
A4: TOTAL TIME NEEDED: 3-4 hours following this guide exactly
A5: STEP 0: INSTALL THESE FIRST (One-time setup - 30 minutes)
A7: # | B7: What to Install | C7: Why You Need It | D7: How to Get It | E7: Time
A8: 1 | B8: Node.js | C8: Runs JavaScript code | D8: Download from nodejs.org - click 'LTS' button, run installer, click Next until done | E8: 5 min
A9: 2 | B9: VS Code | C9: Write and edit code | D9: Download from code.visualstudio.com - run installer | E9: 5 min
A10: 3 | B10: Git | C10: Track code changes | D10: Download from git-scm.com - run installer, keep defaults | E10: 5 min
A11: 4 | B11: MySQL | C11: Database for storing data | D11: Download MySQL Community Server from mysql.com/downloads - remember your password! | E11: 10 min
A12: 5 | B12: Postman | C12: Test your APIs | D12: Download from postman.com - free account | E12: 5 min
A14: STEP 1: CREATE YOUR PROJECT FOLDER (15 minutes)
A16: Open VS Code, then open Terminal (View > Terminal). Type these commands one at a time, press Enter after each:
A18: COMMAND | B18: WHAT IT DOES
A19: mkdir acereads | B19: Creates a folder called 'acereads'
A20: cd acereads | B20: Goes into that folder
A21: npm init -y | B21: Creates package.json (project settings file)
A22: npm install express mysql2 bcrypt jsonwebtoken cors dotenv | B22: Installs the tools you need
A23: mkdir src | B23: Creates src folder for your code
A24: mkdir src/routes src/models src/middleware src/controllers | B24: Creates subfolders to organize code
A25: touch src/app.js (Mac) OR type nul > src\app.js (Windows) | B25: Creates your main app file
A27: STEP 2: CREATE YOUR DATABASE (20 minutes) - THIS COMPLETES T1-001, T1-005, T2-001
A29: Open MySQL Workbench (installed with MySQL). Click the Local instance to connect. Then copy/paste this entire block:
A31: -- COPY EVERYTHING BELOW THIS LINE --
A32: CREATE DATABASE IF NOT EXISTS acereads;
A33: USE acereads;
A35: -- Users table (for login/registration)
A36: CREATE TABLE users (
A37: id INT AUTO_INCREMENT PRIMARY KEY,
A38: email VARCHAR(255) UNIQUE NOT NULL,
A39: password VARCHAR(255) NOT NULL,
A40: first_name VARCHAR(100),
A41: last_name VARCHAR(100),
... A329: In VS Code terminal, make sure you're in the acereads folder, then type:
A331: node src/server.js | B331: Starts your application
A333: You should see: 'AceReads server running on http://localhost:3000'
A335: TO TEST IT WORKS:
A336: Open your web browser and go to: http://localhost:3000/api/health
A337: You should see: { "status": "AceReads API is running!" }
A339: CONGRATULATIONS! Your backend is working!
A341: STEP 9: TEST YOUR APIs WITH POSTMAN (10 min)
...

Sheet Sprint 1 Retrospective
A1: Sprint #1 Retrospective Summary Report
A3: Project: | B3: AceReads
A4: Sprint #: | B4: 1
A5: Sprint Duration: | B5: June 8 - June 21, 2026 (2 weeks)
A6: Sprint Goal: | B6: User Registration, Book Inventory & Search Functionality
A7: Date Completed: | B7: 46194
A9: WHAT WORKED WELL
A10: 1. All 13 sprint tasks were completed on time, achieving 100% completion rate
A11: 2. Team demonstrated strong technical skills - registration, inventory, and search features all functional
A12: 3. Nathan stepped up to take on additional book-related tasks (T1-005, T1-006, T1-007) and delivered
A13: 4. Sprint velocity of 104 story points establishes a solid baseline for future planning
A14: 5. Core functionality (user auth, book inventory, search) delivered as planned for Sprint 1 goal
A16: WHAT DID NOT WORK WELL
A17: 1. Confusion about task ownership - unclear who was responsible for which tasks after team changes
A18: 2. People were added to the team mid-sprint without proper onboarding or task reassignment communication
A19: 3. Lack of communication between team members led to duplicated efforts and misunderstandings
A20: 4. Task descriptions in backlog didn't match what team members thought they were working on (e.g., Nate's task IDs)
A21: 5. No regular check-ins or standups to sync on progress and blockers
A23: HOW THE TEAM WILL IMPROVE
A24: # | B24: Action Item | C24: Owner | D24: Target Date
A25: 1 | B25: Establish daily 15-min standup meetings (in-person or virtual) | C25: Scrum Master | D25: Sprint 2 Day 1
A26: 2 | B26: Create shared task board (Trello/Jira) with clear ownership visible to all | C26: Scrum Master | D26: Sprint 2 Day 1
A27: 3 | B27: Document onboarding checklist for any new team members added mid-project | C27: Product Owner | D27: Sprint 2 Day 3
A28: 4 | B28: Review and update task descriptions in backlog before each sprint to ensure clarity | C28: Product Owner | D28: Before Sprint 3
A29: 5 | B29: Set up team Slack/Teams channel for real-time communication and questions | C29: Development Team | D29: Sprint 2 Day 1
A31: SPRINT METRICS SUMMARY
A32: Total Story Points Committed: | B32: =SUM('Sprint 1'!E11:E23) -> 104
A33: Story Points Completed: | B33: =B32-'Sprint 1'!S25 -> 104
A34: Completion Rate: | B34: =IF(B32=0,0,B33/B32) -> 1
A35: Tasks Completed: | B35: =COUNTIF('Sprint 1'!S11:S23,0) -> 13
A36: Total Tasks: | B36: =COUNTA('Sprint 1'!A11:A23) -> 13
A37: Velocity (points/sprint): | B37: =B33 -> 104
A39: TEAM PARTICIPATION
A40: Team Member | B40: Tasks Assigned | C40: Notes
A41: Ali Osman | B41: =COUNTIF('Sprint 1'!D11:D23,A41) -> 2 | C41: Completed user registration tasks; reassigned book tasks to Nathan
A42: Kyonna Robinson | B42: =COUNTIF('Sprint 1'!D11:D23,A42) -> 2 | C42: Delivered UI components on schedule
A43: Juana Rodriguez | B43: =COUNTIF('Sprint 1'!D11:D23,A43) -> 3 | C43: Completed login system and search backend
A44: Nathan Horstmeier | B44: =COUNTIF('Sprint 1'!D11:D23,A44) -> 6 | C44: Took on 6 tasks including reassigned book schema, CRUD APIs, and admin interface
A45: Phillip Williams | B45: =COUNTIF('Sprint 1'!D11:D23,A45) -> 0 | C45: No Sprint 1 tasks assigned - joined team for Sprint 2
